I'm sorry, but an uncaught exception occurred.

While running game code:
  File "game/script.rpy", line 104, in script
    " Has seleccionado [his_name] ."
KeyError: u'his_name'

-- Full Traceback ------------------------------------------------------------

Full traceback:
  File "game/script.rpy", line 104, in script
    " Has seleccionado [his_name] ."
  File "C:\Program Files (x86)\renpy-6.99.5-sdk\renpy\ast.py", line 594, in execute
    renpy.exports.say(who, what, interact=self.interact)
  File "C:\Program Files (x86)\renpy-6.99.5-sdk\renpy\exports.py", line 1032, in say
    who(what, interact=interact)
  File "C:\Program Files (x86)\renpy-6.99.5-sdk\renpy\character.py", line 817, in __call__
    what = what_pattern.replace("[what]", sub(what, translate=translate))
  File "C:\Program Files (x86)\renpy-6.99.5-sdk\renpy\character.py", line 799, in sub
    return renpy.substitutions.substitute(s, scope=scope, force=force, translate=translate)[0]
  File "C:\Program Files (x86)\renpy-6.99.5-sdk\renpy\substitutions.py", line 229, in substitute
    s = formatter.vformat(s, (), kwargs)
  File "/home/tom/ab/x64lucid-deps/install/lib/python2.7/string.py", line 543, in vformat
  File "/home/tom/ab/x64lucid-deps/install/lib/python2.7/string.py", line 565, in _vformat
  File "/home/tom/ab/x64lucid-deps/install/lib/python2.7/string.py", line 626, in get_field
  File "/home/tom/ab/x64lucid-deps/install/lib/python2.7/string.py", line 585, in get_value
KeyError: u'his_name'

Windows-7-6.1.7601-SP1
Ren'Py 6.99.6.739
Anime Card Battle 0.0
